#VRML_SIM R2021a utf8

# theBitRiddler
# 1/9/2024
# 7:46 PM
# fourWheels Prototype

PROTO Workshop_four_wheeled [
    field SFVec3f translation 0 0 0
    field SFRotation rotation 0 1 0 0
    field SFFloat bodyMass 1
    field SFString controller "four_wheeled_collision_avoidance"
] {
    Robot {
        translation IS translation
        rotation IS rotation
        children [
            DEF BODY Shape {
                appearance PBRAppearance {
                    baseColor 1 0 0
                    roughness 1
                    metalness 0
                }
                geometry Box {
                    size 0.1 0.05 0.2
                }
            }
            DEF WHEEL1 HingeJoint {
                jointParameters HingeJointParameters {
                    anchor 0.06 0 0.05
                }
                device RotationalMotor {
                    name "wheel1"
                }
                endPoint Solid {
                    translation 0.06 0 0.05
                    rotation 0 0 1 1.57
                    children [
                        DEF WHEEL_BODY Shape {
                            appearance DEF WHEEL_APPR PBRAppearance {
                                baseColor 0 1 0
                                roughness 1
                                metalness 0
                            }
                            geometry Cylinder {
                                height 0.02
                                radius 0.04
                            }
                        }
                    ]
                    boundingObject USE WHEEL_BODY
                    physics DEF WHEEL_PH Physics {
                    }
                }
            }
            DEF WHEEL2 HingeJoint {
                jointParameters HingeJointParameters {
                    anchor -0.06 0 0.05
                }
                device RotationalMotor {
                    name "wheel2"
                }
                endPoint Solid {
                    translation -0.06 0 0.05
                    rotation 0 0 1 1.57
                    children USE WHEEL_BODY
                    boundingObject USE WHEEL_BODY
                    physics USE WHEEL_PH
                }
            }
            DEF WHEEL3 HingeJoint {
                jointParameters HingeJointParameters {
                    anchor 0.06 0 -0.05
                }
                device RotationalMotor {
                    name "wheel3"
                }
                endPoint Solid {
                    translation 0.06 0 -0.05
                    rotation 0 0 1 1.57
                    children USE WHEEL_BODY
                    boundingObject USE WHEEL_BODY
                    physics USE WHEEL_PH
                }
            }
            DEF WHEEL4 HingeJoint {
                jointParameters HingeJointParameters {
                    anchor -0.06 0 -0.05
                }
                device RotationalMotor {
                    name "wheel4"
                }
                endPoint Solid {
                    translation -0.06 0 -0.05
                    rotation 0 0 1 1.57
                    children USE WHEEL_BODY
                    boundingObject USE WHEEL_BODY
                    physics USE WHEEL_PH
                }
            }
            DistanceSensor {
                translation 0.03 0 0.1
                rotation 0 1 0 -1.27
                children [
                    DEF SENSOR_BODY Shape {
                        appearance PBRAppearance {
                            baseColor 0 0 1
                            roughness 1
                            metalness 0
                        }
                        geometry Box {
                            size 0.01 0.01 0.01
                        }
                    }
                ]
                name "ds_left"
                boundingObject USE SENSOR_BODY
                physics DEF DS_PH Physics {
                }
            }
            DistanceSensor {
                translation -0.03 0 0.1
                rotation 0 1 0 4.41
                children USE SENSOR_BODY
                name "ds_right"
                boundingObject USE SENSOR_BODY
                physics USE DS_PH
            }
        ]
        boundingObject USE BODY
        physics Physics {
            mass IS bodyMass
        }
        controller IS controller
    }
}